Workbook

Sheet Portfolio Summary
A1: Multi-Brand Franchise Portfolio — Executive Summary
A2: Little Caesars (4 units) | Arby's (3 units) | Wingstop (3 units) | FY 2025 | USD
A4: Metric | B4: Little Caesars | C4: Arby's | D4: Wingstop | E4: Portfolio Total
A5: Total Revenue (FY) | B5: =('Little Caesars Location 1'!O26+'Little Caesars Location 2'!O26+'Little Caesars Location 3'!O26+'Little Caesars Location 4'!O26) -> 2916000 | C5: =('Arbys Location 1'!O26+'Arbys Location 2'!O26+'Arbys Location 3'!O26) -> 2652000 | D5: =('Wingstop Location 1'!O26+'Wingstop Location 2'!O26+'Wingstop Location 3'!O26) -> 2928000 | E5: =('Little Caesars Location 1'!O26+'Little Caesars Location 2'!O26+'Little Caesars Location 3'!O26+'Little Caesars Location 4'!O26+'Arbys Location 1'!O26+'Arbys Location 2'!O26+'Arbys Location 3'!O26+'Wingstop Location 1'!O26+'Wingstop Location 2'!O26+'Wingstop Location 3'!O26) -> 8496000
A6: Total COGS | B6: =('Little Caesars Location 1'!O31+'Little Caesars Location 2'!O31+'Little Caesars Location 3'!O31+'Little Caesars Location 4'!O31) -> 858373.2 | C6: =('Arbys Location 1'!O31+'Arbys Location 2'!O31+'Arbys Location 3'!O31) -> 852542.86 | D6: =('Wingstop Location 1'!O31+'Wingstop Location 2'!O31+'Wingstop Location 3'!O31) -> 1049700.2 | E6: =('Little Caesars Location 1'!O31+'Little Caesars Location 2'!O31+'Little Caesars Location 3'!O31+'Little Caesars Location 4'!O31+'Arbys Location 1'!O31+'Arbys Location 2'!O31+'Arbys Location 3'!O31+'Wingstop Location 1'!O31+'Wingstop Location 2'!O31+'Wingstop Location 3'!O31) -> 2760616.3
A7: Gross Profit | B7: =('Little Caesars Location 1'!O33+'Little Caesars Location 2'!O33+'Little Caesars Location 3'!O33+'Little Caesars Location 4'!O33) -> 2057626.8 | C7: =('Arbys Location 1'!O33+'Arbys Location 2'!O33+'Arbys Location 3'!O33) -> 1799457.1 | D7: =('Wingstop Location 1'!O33+'Wingstop Location 2'!O33+'Wingstop Location 3'!O33) -> 1878299.8 | E7: =('Little Caesars Location 1'!O33+'Little Caesars Location 2'!O33+'Little Caesars Location 3'!O33+'Little Caesars Location 4'!O33+'Arbys Location 1'!O33+'Arbys Location 2'!O33+'Arbys Location 3'!O33+'Wingstop Location 1'!O33+'Wingstop Location 2'!O33+'Wingstop Location 3'!O33) -> 5735383.7
A8: Gross Margin % | B8: =IF(('Little Caesars Location 1'!O26+'Little Caesars Location 2'!O26+'Little Caesars Location 3'!O26+'Little Caesars Location 4'!O26)=0,0,('Little Caesars Location 1'!O33+'Little Caesars Location 2'!O33+'Little Caesars Location 3'!O33+'Little Caesars Location 4'!O33)/('Little Caesars Location 1'!O26+'Little Caesars Location 2'!O26+'Little Caesars Location 3'!O26+'Little Caesars Location 4'!O26)) -> 0.70563333 | C8: =IF(('Arbys Location 1'!O26+'Arbys Location 2'!O26+'Arbys Location 3'!O26)=0,0,('Arbys Location 1'!O33+'Arbys Location 2'!O33+'Arbys Location 3'!O33)/('Arbys Location 1'!O26+'Arbys Location 2'!O26+'Arbys Location 3'!O26)) -> 0.67852833 | D8: =IF(('Wingstop Location 1'!O26+'Wingstop Location 2'!O26+'Wingstop Location 3'!O26)=0,0,('Wingstop Location 1'!O33+'Wingstop Location 2'!O33+'Wingstop Location 3'!O33)/('Wingstop Location 1'!O26+'Wingstop Location 2'!O26+'Wingstop Location 3'!O26)) -> 0.64149583 | E8: =IF(('Little Caesars Location 1'!O26+'Little Caesars Location 2'!O26+'Little Caesars Location 3'!O26+'Little Caesars Location 4'!O26+'Arbys Location 1'!O26+'Arbys Location 2'!O26+'Arbys Location 3'!O26+'Wingstop Location 1'!O26+'Wingstop Location 2'!O26+'Wingstop Location 3'!O26)=0,0,('Little Caesars Location 1'!O33+'Little Caesars Location 2'!O33+'Little Caesars Location 3'!O33+'Little Caesars Location 4'!O33+'Arbys Location 1'!O33+'Arbys Location 2'!O33+'Arbys Location 3'!O33+'Wingstop Location 1'!O33+'Wingstop Location 2'!O33+'Wingstop Location 3'!O33)/('Little Caesars Location 1'!O26+'Little Caesars Location 2'!O26+'Little Caesars Location 3'!O26+'Little Caesars Location 4'!O26+'Arbys Location 1'!O26+'Arbys Location 2'!O26+'Arbys Location 3'!O26+'Wingstop Location 1'!O26+'Wingstop Location 2'!O26+'Wingstop Location 3'!O26)) -> 0.67506871
A9: Total OpEx | B9: =('Little Caesars Location 1'!O43+'Little Caesars Location 2'!O43+'Little Caesars Location 3'!O43+'Little Caesars Location 4'!O43) -> 1275204 | C9: =('Arbys Location 1'!O43+'Arbys Location 2'!O43+'Arbys Location 3'!O43) -> 1113102 | D9: =('Wingstop Location 1'!O43+'Wingstop Location 2'!O43+'Wingstop Location 3'!O43) -> 1160130 | E9: =('Little Caesars Location 1'!O43+'Little Caesars Location 2'!O43+'Little Caesars Location 3'!O43+'Little Caesars Location 4'!O43+'Arbys Location 1'!O43+'Arbys Location 2'!O43+'Arbys Location 3'!O43+'Wingstop Location 1'!O43+'Wingstop Location 2'!O43+'Wingstop Location 3'!O43) -> 3548436
A10: EBITDA | B10: =('Little Caesars Location 1'!O45+'Little Caesars Location 2'!O45+'Little Caesars Location 3'!O45+'Little Caesars Location 4'!O45) -> 782422.8 | C10: =('Arbys Location 1'!O45+'Arbys Location 2'!O45+'Arbys Location 3'!O45) -> 686355.14 | D10: =('Wingstop Location 1'!O45+'Wingstop Location 2'!O45+'Wingstop Location 3'!O45) -> 718169.8 | E10: =('Little Caesars Location 1'!O45+'Little Caesars Location 2'!O45+'Little Caesars Location 3'!O45+'Little Caesars Location 4'!O45+'Arbys Location 1'!O45+'Arbys Location 2'!O45+'Arbys Location 3'!O45+'Wingstop Location 1'!O45+'Wingstop Location 2'!O45+'Wingstop Location 3'!O45) -> 2186947.7
A11: EBITDA Margin % | B11: =IF(('Little Caesars Location 1'!O26+'Little Caesars Location 2'!O26+'Little Caesars Location 3'!O26+'Little Caesars Location 4'!O26)=0,0,('Little Caesars Location 1'!O45+'Little Caesars Location 2'!O45+'Little Caesars Location 3'!O45+'Little Caesars Location 4'!O45)/('Little Caesars Location 1'!O26+'Little Caesars Location 2'!O26+'Little Caesars Location 3'!O26+'Little Caesars Location 4'!O26)) -> 0.26832058 | C11: =IF(('Arbys Location 1'!O26+'Arbys Location 2'!O26+'Arbys Location 3'!O26)=0,0,('Arbys Location 1'!O45+'Arbys Location 2'!O45+'Arbys Location 3'!O45)/('Arbys Location 1'!O26+'Arbys Location 2'!O26+'Arbys Location 3'!O26)) -> 0.25880661 | D11: =IF(('Wingstop Location 1'!O26+'Wingstop Location 2'!O26+'Wingstop Location 3'!O26)=0,0,('Wingstop Location 1'!O45+'Wingstop Location 2'!O45+'Wingstop Location 3'!O45)/('Wingstop Location 1'!O26+'Wingstop Location 2'!O26+'Wingstop Location 3'!O26)) -> 0.24527657 | E11: =IF(('Little Caesars Location 1'!O26+'Little Caesars Location 2'!O26+'Little Caesars Location 3'!O26+'Little Caesars Location 4'!O26+'Arbys Location 1'!O26+'Arbys Location 2'!O26+'Arbys Location 3'!O26+'Wingstop Location 1'!O26+'Wingstop Location 2'!O26+'Wingstop Location 3'!O26)=0,0,('Little Caesars Location 1'!O45+'Little Caesars Location 2'!O45+'Little Caesars Location 3'!O45+'Little Caesars Location 4'!O45+'Arbys Location 1'!O45+'Arbys Location 2'!O45+'Arbys Location 3'!O45+'Wingstop Location 1'!O45+'Wingstop Location 2'!O45+'Wingstop Location 3'!O45)/('Little Caesars Location 1'!O26+'Little Caesars Location 2'!O26+'Little Caesars Location 3'!O26+'Little Caesars Location 4'!O26+'Arbys Location 1'!O26+'Arbys Location 2'!O26+'Arbys Location 3'!O26+'Wingstop Location 1'!O26+'Wingstop Location 2'!O26+'Wingstop Location 3'!O26)) -> 0.2574091
A14: LOCATION DETAIL — ANNUAL REVENUE & EBITDA
A15: Location | B15: Annual Revenue | C15: Gross Profit | D15: EBITDA | E15: EBITDA Margin
A16: Little Caesars Location 1 | B16: ='Little Caesars Location 1'!O26 -> 720000 | C16: ='Little Caesars Location 1'!O33 -> 508056 | D16: ='Little Caesars Location 1'!O45 -> 193095 | E16: =IF(B16=0,0,D16/B16) -> 0.2681875
A17: Little Caesars Location 2 | B17: ='Little Caesars Location 2'!O26 -> 756000 | C17: ='Little Caesars Location 2'!O33 -> 533458.8 | D17: ='Little Caesars Location 2'!O45 -> 206737.8 | E17: =IF(B17=0,0,D17/B17) -> 0.2734627
A18: Little Caesars Location 3 | B18: ='Little Caesars Location 3'!O26 -> 696000 | C18: ='Little Caesars Location 3'!O33 -> 491120.8 | D18: ='Little Caesars Location 3'!O45 -> 183599.8 | E18: =IF(B18=0,0,D18/B18) -> 0.26379282
A19: Little Caesars Location 4 | B19: ='Little Caesars Location 4'!O26 -> 744000 | C19: ='Little Caesars Location 4'!O33 -> 524991.2 | D19: ='Little Caesars Location 4'!O45 -> 198990.2 | E19: =IF(B19=0,0,D19/B19) -> 0.26745995
A20: Arby's Location 1 | B20: ='Arbys Location 1'!O26 -> 900000 | C20: ='Arbys Location 1'!O33 -> 610675.5 | D20: ='Arbys Location 1'!O45 -> 235561.5 | E20: =IF(B20=0,0,D20/B20) -> 0.261735
A21: Arby's Location 2 | B21: ='Arbys Location 2'!O26 -> 864000 | C21: ='Arbys Location 2'!O33 -> 586248.48 | D21: ='Arbys Location 2'!O45 -> 223014.48 | E21: =IF(B21=0,0,D21/B21) -> 0.25811861
A22: Arby's Location 3 | B22: ='Arbys Location 3'!O26 -> 888000 | C22: ='Arbys Location 3'!O33 -> 602533.16 | D22: ='Arbys Location 3'!O45 -> 227779.16 | E22: =IF(B22=0,0,D22/B22) -> 0.25650806
A23: Wingstop Location 1 | B23: ='Wingstop Location 1'!O26 -> 984000 | C23: ='Wingstop Location 1'!O33 -> 631231.9 | D23: ='Wingstop Location 1'!O45 -> 244921.9 | E23: =IF(B23=0,0,D23/B23) -> 0.24890437
A24: Wingstop Location 2 | B24: ='Wingstop Location 2'!O26 -> 960000 | C24: ='Wingstop Location 2'!O33 -> 615836 | D24: ='Wingstop Location 2'!O45 -> 233126 | E24: =IF(B24=0,0,D24/B24) -> 0.24283958
A25: Wingstop Location 3 | B25: ='Wingstop Location 3'!O26 -> 984000 | C25: ='Wingstop Location 3'!O33 -> 631231.9 | D25: ='Wingstop Location 3'!O45 -> 240121.9 | E25: =IF(B25=0,0,D25/B25) -> 0.24402632
A26: Portfolio Total | B26: =SUM(B16:B25) -> 8496000 | C26: =SUM(C16:C25) -> 5735383.7 | D26: =SUM(D16:D25) -> 2186947.7 | E26: =IF(B26=0,0,D26/B26) -> 0.2574091
A28: KEY INSIGHTS — SEASONAL DRIVERS
A29: • Little Caesars: Peaks May–Aug (summer family nights) + Feb Super Bowl + Oct Halloween. Slowest in Mar/Apr/Nov.
A30: • Arby's: Most consistent brand; drive-thru efficiency keeps labor lower (~20% variable). Slight summer dip only.
A31: • Wingstop: Feb Super Bowl is the highest single revenue month (+35% above avg). NFL season (Sep–Nov) sustains elevated sales.
A32: • Wing commodity prices spike around Super Bowl — Feb food cost adj (+3.5%) is built into the Wingstop model.
A33: • All seasonal indices are editable (yellow cells). Change any value and full P&L recalculates instantly.

Sheet Little Caesars Location 1
A1: Little Caesars — Location 1 | Monthly P&L
A2: Blue = Editable Input | Black = Formula | Green = Linked | Yellow = Assumption cell | Amber = Seasonal index
A3: ASSUMPTIONS
A4: Monthly Base Revenue ($) | B4: 60000
A5: Food & Beverage Cost — Base (%) | B5: 0.27
A6: Paper & Supplies (%) | B6: 0.02
A7: Variable Labor (% of Revenue) | B7: 0.22
A8: Fixed Labor — Mgmt / Base Crew ($) | B8: 3500
A9: Monthly Rent ($) | B9: 5600
A10: Utilities — Base ($/mo) | B10: 1100
A11: Marketing (% of Revenue) | B11: 0.04
A12: Misc / Other ($/mo) | B12: 400
A14: MONTHLY SEASONAL INDICES (edit to model scenarios)
B15: Jan | C15: Feb | D15: Mar | E15: Apr | F15: May | G15: Jun | H15: Jul | I15: Aug | J15: Sep | K15: Oct | L15: Nov | M15: Dec | O15: Full Yr Avg | P15: Notes
A16: Revenue Index | B16: 1 | C16: 1.12 | D16: 0.82 | E16: 0.85 | F16: 1.08 | G16: 1.18 | H16: 1.22 | I16: 1.15 | J16: 0.88 | K16: 1.05 | L16: 0.82 | M16: 0.83 | O16: =AVERAGE(B16:M16) -> 1 | P16: 1.00=avg month. >1.00=above avg revenue.
A17: Food Cost Adj (%) | B17: 0 | C17: 0 | D17: 0 | E17: 0 | F17: 0.01 | G17: 0.01 | H17: 0.015 | I17: 0.01 | J17: 0 | K17: 0 | L17: 0 | M17: 0 | O17: =AVERAGE(B17:M17) -> 0.00375 | P17: Added to base food %. Commodity/demand swings.
A18: Utility Seasonal Factor | B18: 1.15 | C18: 1.15 | D18: 1 | E18: 0.9 | F18: 0.95 | G18: 1.05 | H18: 1.18 | I18: 1.18 | J18: 0.95 | K18: 0.9 | L18: 1 | M18: 1.1 | O18: =AVERAGE(B18:M18) -> 1.0425 | P18: Multiplied by base utility $. Weather-driven.
A20: MONTHLY PROFIT & LOSS
A21: Line Item | B21: Jan | C21: Feb | D21: Mar | E21: Apr | F21: May | G21: Jun | H21: Jul | I21: Aug | J21: Sep | K21: Oct | L21: Nov | M21: Dec | N21: Full Year | O21: % of Rev
A22: REVENUE
A23: In-Store / Counter | B23: =$B$4*B$16*0.35 -> 21000 | C23: =$B$4*C$16*0.35 -> 23520 | D23: =$B$4*D$16*0.35 -> 17220 | E23: =$B$4*E$16*0.35 -> 17850 | F23: =$B$4*F$16*0.35 -> 22680 | G23: =$B$4*G$16*0.35 -> 24780 | H23: =$B$4*H$16*0.35 -> 25620 | I23: =$B$4*I$16*0.35 -> 24150 | ... M23: =$B$4*M$16*0.35 -> 17430 | O23: =SUM(B23:M23) -> 252000 | P23: =IF(O26=0,0,O23/O26) -> 0.35
A24: Delivery / Pickup | B24: =$B$4*B$16*0.55 -> 33000 | C24: =$B$4*C$16*0.55 -> 36960 | D24: =$B$4*D$16*0.55 -> 27060 | E24: =$B$4*E$16*0.55 -> 28050 | F24: =$B$4*F$16*0.55 -> 35640 | G24: =$B$4*G$16*0.55 -> 38940 | H24: =$B$4*H$16*0.55 -> 40260 | I24: =$B$4*I$16*0.55 -> 37950 | ... M24: =$B$4*M$16*0.55 -> 27390 | O24: =SUM(B24:M24) -> 396000 | P24: =IF(O26=0,0,O24/O26) -> 0.55
A25: Catering / Online | B25: =$B$4*B$16*0.1 -> 6000 | C25: =$B$4*C$16*0.1 -> 6720 | D25: =$B$4*D$16*0.1 -> 4920 | E25: =$B$4*E$16*0.1 -> 5100 | F25: =$B$4*F$16*0.1 -> 6480 | G25: =$B$4*G$16*0.1 -> 7080 | H25: =$B$4*H$16*0.1 -> 7320 | I25: =$B$4*I$16*0.1 -> 6900 | ... M25: =$B$4*M$16*0.1 -> 4980 | O25: =SUM(B25:M25) -> 72000 | P25: =IF(O26=0,0,O25/O26) -> 0.1
A26: Total Revenue | B26: =B23+B24+B25 -> 60000 | C26: =C23+C24+C25 -> 67200 | D26: =D23+D24+D25 -> 49200 | E26: =E23+E24+E25 -> 51000 | F26: =F23+F24+F25 -> 64800 | G26: =G23+G24+G25 -> 70800 | H26: =H23+H24+H25 -> 73200 | I26: =I23+I24+I25 -> 69000 | ... M26: =M23+M24+M25 -> 49800 | O26: =SUM(B26:M26) -> 720000 | P26: =IF(O26=0,0,O26/O26) -> 1
A28: COST OF GOODS SOLD
A29: Food & Beverage Cost | B29: =B26*($B$5+B$17) -> 16200 | C29: =C26*($B$5+C$17) -> 18144 | D29: =D26*($B$5+D$17) -> 13284 | E29: =E26*($B$5+E$17) -> 13770 | F29: =F26*($B$5+F$17) -> 18144 | G29: =G26*($B$5+G$17) -> 19824 | H29: =H26*($B$5+H$17) -> 20862 | I29: =I26*($B$5+I$17) -> 19320 | ... M29: =M26*($B$5+M$17) -> 13446 | O29: =SUM(B29:M29) -> 197544 | P29: =IF(O26=0,0,O29/O26) -> 0.27436667
A30: Paper & Supplies | B30: =B26*$B$6 -> 1200 | C30: =C26*$B$6 -> 1344 | D30: =D26*$B$6 -> 984 | E30: =E26*$B$6 -> 1020 | F30: =F26*$B$6 -> 1296 | G30: =G26*$B$6 -> 1416 | H30: =H26*$B$6 -> 1464 | I30: =I26*$B$6 -> 1380 | ... M30: =M26*$B$6 -> 996 | O30: =SUM(B30:M30) -> 14400 | P30: =IF(O26=0,0,O30/O26) -> 0.02
A31: Total COGS | B31: =B29+B30 -> 17400 | C31: =C29+C30 -> 19488 | D31: =D29+D30 -> 14268 | E31: =E29+E30 -> 14790 | F31: =F29+F30 -> 19440 | G31: =G29+G30 -> 21240 | H31: =H29+H30 -> 22326 | I31: =I29+I30 -> 20700 | ... M31: =M29+M30 -> 14442 | O31: =SUM(B31:M31) -> 211944 | P31: =IF(O26=0,0,O31/O26) -> 0.29436667
A33: GROSS PROFIT | B33: =B26-B31 -> 42600 | C33: =C26-C31 -> 47712 | D33: =D26-D31 -> 34932 | E33: =E26-E31 -> 36210 | F33: =F26-F31 -> 45360 | G33: =G26-G31 -> 49560 | H33: =H26-H31 -> 50874 | I33: =I26-I31 -> 48300 | ... M33: =M26-M31 -> 35358 | O33: =SUM(B33:M33) -> 508056 | P33: =IF(O26=0,0,O33/O26) -> 0.70563333
A34: Gross Margin % | B34: =IF(B26=0,0,B33/B26) -> 0.71 | C34: =IF(C26=0,0,C33/C26) -> 0.71 | D34: =IF(D26=0,0,D33/D26) -> 0.71 | E34: =IF(E26=0,0,E33/E26) -> 0.71 | F34: =IF(F26=0,0,F33/F26) -> 0.7 | G34: =IF(G26=0,0,G33/G26) -> 0.7 | H34: =IF(H26=0,0,H33/H26) -> 0.695 | I34: =IF(I26=0,0,I33/I26) -> 0.7 | ... M34: =IF(M26=0,0,M33/M26) -> 0.71 | O34: =IF(O26=0,0,O33/O26) -> 0.70563333 | P34: =IF(O26=0,0,O33/O26) -> 0.70563333
A36: OPERATING EXPENSES
A37: Variable Labor | B37: =B26*$B$7 -> 13200 | C37: =C26*$B$7 -> 14784 | D37: =D26*$B$7 -> 10824 | E37: =E26*$B$7 -> 11220 | F37: =F26*$B$7 -> 14256 | G37: =G26*$B$7 -> 15576 | H37: =H26*$B$7 -> 16104 | I37: =I26*$B$7 -> 15180 | ... M37: =M26*$B$7 -> 10956 | O37: =SUM(B37:M37) -> 158400 | P37: =IF(O26=0,0,O37/O26) -> 0.22
A38: Fixed Labor (Mgmt / Base Crew) | B38: =$B$8 -> 3500 | C38: =$B$8 -> 3500 | D38: =$B$8 -> 3500 | E38: =$B$8 -> 3500 | F38: =$B$8 -> 3500 | G38: =$B$8 -> 3500 | H38: =$B$8 -> 3500 | I38: =$B$8 -> 3500 | ... M38: =$B$8 -> 3500 | O38: =SUM(B38:M38) -> 42000 | P38: =IF(O26=0,0,O38/O26) -> 0.058333333
A39: Rent | B39: =$B$9 -> 5600 | C39: =$B$9 -> 5600 | D39: =$B$9 -> 5600 | E39: =$B$9 -> 5600 | F39: =$B$9 -> 5600 | G39: =$B$9 -> 5600 | H39: =$B$9 -> 5600 | I39: =$B$9 -> 5600 | ... M39: =$B$9 -> 5600 | O39: =SUM(B39:M39) -> 67200 | P39: =IF(O26=0,0,O39/O26) -> 0.093333333
A40: Utilities | B40: =$B$10*B$18 -> 1265 | C40: =$B$10*C$18 -> 1265 | D40: =$B$10*D$18 -> 1100 | E40: =$B$10*E$18 -> 990 | F40: =$B$10*F$18 -> 1045 | G40: =$B$10*G$18 -> 1155 | H40: =$B$10*H$18 -> 1298 | I40: =$B$10*I$18 -> 1298 | ... M40: =$B$10*M$18 -> 1210 | O40: =SUM(B40:M40) -> 13761 | P40: =IF(O26=0,0,O40/O26) -> 0.0191125
A41: Marketing | B41: =B26*$B$11 -> 2400 | C41: =C26*$B$11 -> 2688 | D41: =D26*$B$11 -> 1968 | E41: =E26*$B$11 -> 2040 | F41: =F26*$B$11 -> 2592 | G41: =G26*$B$11 -> 2832 | H41: =H26*$B$11 -> 2928 | I41: =I26*$B$11 -> 2760 | ... M41: =M26*$B$11 -> 1992 | O41: =SUM(B41:M41) -> 28800 | P41: =IF(O26=0,0,O41/O26) -> 0.04
A42: Misc / Other | B42: =$B$12 -> 400 | C42: =$B$12 -> 400 | D42: =$B$12 -> 400 | E42: =$B$12 -> 400 | F42: =$B$12 -> 400 | G42: =$B$12 -> 400 | H42: =$B$12 -> 400 | I42: =$B$12 -> 400 | ... M42: =$B$12 -> 400 | O42: =SUM(B42:M42) -> 4800 | P42: =IF(O26=0,0,O42/O26) -> 0.0066666667
A43: Total OpEx | B43: =B37+B38+B39+B40+B41+B42 -> 26365 | C43: =C37+C38+C39+C40+C41+C42 -> 28237 | D43: =D37+D38+D39+D40+D41+D42 -> 23392 | E43: =E37+E38+E39+E40+E41+E42 -> 23750 | F43: =F37+F38+F39+F40+F41+F42 -> 27393 | G43: =G37+G38+G39+G40+G41+G42 -> 29063 | H43: =H37+H38+H39+H40+H41+H42 -> 29830 | I43: =I37+I38+I39+I40+I41+I42 -> 28738 | ... M43: =M37+M38+M39+M40+M41+M42 -> 23658 | O43: =SUM(B43:M43) -> 314961 | P43: =IF(O26=0,0,O43/O26) -> 0.43744583
A45: NET OPERATING INCOME (EBITDA) | B45: =B33-B43 -> 16235 | C45: =C33-C43 -> 19475 | D45: =D33-D43 -> 11540 | E45: =E33-E43 -> 12460 | F45: =F33-F43 -> 17967 | G45: =G33-G43 -> 20497 | H45: =H33-H43 -> 21044 | I45: =I33-I43 -> 19562 | ... M45: =M33-M43 -> 11700 | O45: =SUM(B45:M45) -> 193095 | P45: =IF(O26=0,0,O45/O26) -> 0.2681875
A46: NOI Margin % | B46: =IF(B26=0,0,B45/B26) -> 0.27058333 | C46: =IF(C26=0,0,C45/C26) -> 0.28980655 | D46: =IF(D26=0,0,D45/D26) -> 0.23455285 | E46: =IF(E26=0,0,E45/E26) -> 0.24431373 | F46: =IF(F26=0,0,F45/F26) -> 0.27726852 | G46: =IF(G26=0,0,G45/G26) -> 0.28950565 | H46: =IF(H26=0,0,H45/H26) -> 0.28748634 | I46: =IF(I26=0,0,I45/I26) -> 0.28350725 | ... M46: =IF(M26=0,0,M45/M26) -> 0.23493976 | O46: =IF(O26=0,0,O45/O26) -> 0.2681875 | P46: =IF(O26=0,0,O45/O26) -> 0.2681875

Sheet Little Caesars Location 2
A1: Little Caesars — Location 2 | Monthly P&L
A2: Blue = Editable Input | Black = Formula | Green = Linked | Yellow = Assumption cell | Amber = Seasonal index
A3: ASSUMPTIONS
A4: Monthly Base Revenue ($) | B4: 63000
A5: Food & Beverage Cost — Base (%) | B5: 0.27
A6: Paper & Supplies (%) | B6: 0.02
A7: Variable Labor (% of Revenue) | B7: 0.22
A8: Fixed Labor — Mgmt / Base Crew ($) | B8: 3500
A9: Monthly Rent ($) | B9: 5800
A10: Utilities — Base ($/mo) | B10: 1100
A11: Marketing (% of Revenue) | B11: 0.04
A12: Misc / Other ($/mo) | B12: 400
A14: MONTHLY SEASONAL INDICES (edit to model scenarios)
B15: Jan | C15: Feb | D15: Mar | E15: Apr | F15: May | G15: Jun | H15: Jul | I15: Aug | J15: Sep | K15: Oct | L15: Nov | M15: Dec | O15: Full Yr Avg | P15: Notes
A16: Revenue Index | B16: 1 | C16: 1.12 | D16: 0.82 | E16: 0.85 | F16: 1.08 | G16: 1.18 | H16: 1.22 | I16: 1.15 | J16: 0.88 | K16: 1.05 | L16: 0.82 | M16: 0.83 | O16: =AVERAGE(B16:M16) -> 1 | P16: 1.00=avg month. >1.00=above avg revenue.
A17: Food Cost Adj (%) | B17: 0 | C17: 0 | D17: 0 | E17: 0 | F17: 0.01 | G17: 0.01 | H17: 0.015 | I17: 0.01 | J17: 0 | K17: 0 | L17: 0 | M17: 0 | O17: =AVERAGE(B17:M17) -> 0.00375 | P17: Added to base food %. Commodity/demand swings.
A18: Utility Seasonal Factor | B18: 1.15 | C18: 1.15 | D18: 1 | E18: 0.9 | F18: 0.95 | G18: 1.05 | H18: 1.18 | I18: 1.18 | J18: 0.95 | K18: 0.9 | L18: 1 | M18: 1.1 | O18: =AVERAGE(B18:M18) -> 1.0425 | P18: Multiplied by base utility $. Weather-driven.
A20: MONTHLY PROFIT & LOSS
A21: Line Item | B21: Jan | C21: Feb | D21: Mar | E21: Apr | F21: May | G21: Jun | H21: Jul | I21: Aug | J21: Sep | K21: Oct | L21: Nov | M21: Dec | N21: Full Year | O21: % of Rev
A22: REVENUE
A23: In-Store / Counter | B23: =$B$4*B$16*0.35 -> 22050 | C23: =$B$4*C$16*0.35 -> 24696 | D23: =$B$4*D$16*0.35 -> 18081 | E23: =$B$4*E$16*0.35 -> 18742.5 | F23: =$B$4*F$16*0.35 -> 23814 | G23: =$B$4*G$16*0.35 -> 26019 | H23: =$B$4*H$16*0.35 -> 26901 | I23: =$B$4*I$16*0.35 -> 25357.5 | ... M23: =$B$4*M$16*0.35 -> 18301.5 | O23: =SUM(B23:M23) -> 264600 | P23: =IF(O26=0,0,O23/O26) -> 0.35
A24: Delivery / Pickup | B24: =$B$4*B$16*0.55 -> 34650 | C24: =$B$4*C$16*0.55 -> 38808 | D24: =$B$4*D$16*0.55 -> 28413 | E24: =$B$4*E$16*0.55 -> 29452.5 | F24: =$B$4*F$16*0.55 -> 37422 | G24: =$B$4*G$16*0.55 -> 40887 | H24: =$B$4*H$16*0.55 -> 42273 | I24: =$B$4*I$16*0.55 -> 39847.5 | ... M24: =$B$4*M$16*0.55 -> 28759.5 | O24: =SUM(B24:M24) -> 415800 | P24: =IF(O26=0,0,O24/O26) -> 0.55
A25: Catering / Online | B25: =$B$4*B$16*0.1 -> 6300 | C25: =$B$4*C$16*0.1 -> 7056 | D25: =$B$4*D$16*0.1 -> 5166 | E25: =$B$4*E$16*0.1 -> 5355 | F25: =$B$4*F$16*0.1 -> 6804 | G25: =$B$4*G$16*0.1 -> 7434 | H25: =$B$4*H$16*0.1 -> 7686 | I25: =$B$4*I$16*0.1 -> 7245 | ... M25: =$B$4*M$16*0.1 -> 5229 | O25: =SUM(B25:M25) -> 75600 | P25: =IF(O26=0,0,O25/O26) -> 0.1
A26: Total Revenue | B26: =B23+B24+B25 -> 63000 | C26: =C23+C24+C25 -> 70560 | D26: =D23+D24+D25 -> 51660 | E26: =E23+E24+E25 -> 53550 | F26: =F23+F24+F25 -> 68040 | G26: =G23+G24+G25 -> 74340 | H26: =H23+H24+H25 -> 76860 | I26: =I23+I24+I25 -> 72450 | ... M26: =M23+M24+M25 -> 52290 | O26: =SUM(B26:M26) -> 756000 | P26: =IF(O26=0,0,O26/O26) -> 1
A28: COST OF GOODS SOLD
A29: Food & Beverage Cost | B29: =B26*($B$5+B$17) -> 17010 | C29: =C26*($B$5+C$17) -> 19051.2 | D29: =D26*($B$5+D$17) -> 13948.2 | E29: =E26*($B$5+E$17) -> 14458.5 | F29: =F26*($B$5+F$17) -> 19051.2 | G29: =G26*($B$5+G$17) -> 20815.2 | H29: =H26*($B$5+H$17) -> 21905.1 | I29: =I26*($B$5+I$17) -> 20286 | ... M29: =M26*($B$5+M$17) -> 14118.3 | O29: =SUM(B29:M29) -> 207421.2 | P29: =IF(O26=0,0,O29/O26) -> 0.27436667
A30: Paper & Supplies | B30: =B26*$B$6 -> 1260 | C30: =C26*$B$6 -> 1411.2 | D30: =D26*$B$6 -> 1033.2 | E30: =E26*$B$6 -> 1071 | F30: =F26*$B$6 -> 1360.8 | G30: =G26*$B$6 -> 1486.8 | H30: =H26*$B$6 -> 1537.2 | I30: =I26*$B$6 -> 1449 | ... M30: =M26*$B$6 -> 1045.8 | O30: =SUM(B30:M30) -> 15120 | P30: =IF(O26=0,0,O30/O26) -> 0.02
A31: Total COGS | B31: =B29+B30 -> 18270 | C31: =C29+C30 -> 20462.4 | D31: =D29+D30 -> 14981.4 | E31: =E29+E30 -> 15529.5 | F31: =F29+F30 -> 20412 | G31: =G29+G30 -> 22302 | H31: =H29+H30 -> 23442.3 | I31: =I29+I30 -> 21735 | ... M31: =M29+M30 -> 15164.1 | O31: =SUM(B31:M31) -> 222541.2 | P31: =IF(O26=0,0,O31/O26) -> 0.29436667
A33: GROSS PROFIT | B33: =B26-B31 -> 44730 | C33: =C26-C31 -> 50097.6 | D33: =D26-D31 -> 36678.6 | E33: =E26-E31 -> 38020.5 | F33: =F26-F31 -> 47628 | G33: =G26-G31 -> 52038 | H33: =H26-H31 -> 53417.7 | I33: =I26-I31 -> 50715 | ... M33: =M26-M31 -> 37125.9 | O33: =SUM(B33:M33) -> 533458.8 | P33: =IF(O26=0,0,O33/O26) -> 0.70563333
A34: Gross Margin % | B34: =IF(B26=0,0,B33/B26) -> 0.71 | C34: =IF(C26=0,0,C33/C26) -> 0.71 | D34: =IF(D26=0,0,D33/D26) -> 0.71 | E34: =IF(E26=0,0,E33/E26) -> 0.71 | F34: =IF(F26=0,0,F33/F26) -> 0.7 | G34: =IF(G26=0,0,G33/G26) -> 0.7 | H34: =IF(H26=0,0,H33/H26) -> 0.695 | I34: =IF(I26=0,0,I33/I26) -> 0.7 | ... M34: =IF(M26=0,0,M33/M26) -> 0.71 | O34: =IF(O26=0,0,O33/O26) -> 0.70563333 | P34: =IF(O26=0,0,O33/O26) -> 0.70563333
A36: OPERATING EXPENSES
A37: Variable Labor | B37: =B26*$B$7 -> 13860 | C37: =C26*$B$7 -> 15523.2 | D37: =D26*$B$7 -> 11365.2 | E37: =E26*$B$7 -> 11781 | F37: =F26*$B$7 -> 14968.8 | G37: =G26*$B$7 -> 16354.8 | H37: =H26*$B$7 -> 16909.2 | I37: =I26*$B$7 -> 15939 | ... M37: =M26*$B$7 -> 11503.8 | O37: =SUM(B37:M37) -> 166320 | P37: =IF(O26=0,0,O37/O26) -> 0.22
A38: Fixed Labor (Mgmt / Base Crew) | B38: =$B$8 -> 3500 | C38: =$B$8 -> 3500 | D38: =$B$8 -> 3500 | E38: =$B$8 -> 3500 | F38: =$B$8 -> 3500 | G38: =$B$8 -> 3500 | H38: =$B$8 -> 3500 | I38: =$B$8 -> 3500 | ... M38: =$B$8 -> 3500 | O38: =SUM(B38:M38) -> 42000 | P38: =IF(O26=0,0,O38/O26) -> 0.055555556
A39: Rent | B39: =$B$9 -> 5800 | C39: =$B$9 -> 5800 | D39: =$B$9 -> 5800 | E39: =$B$9 -> 5800 | F39: =$B$9 -> 5800 | G39: =$B$9 -> 5800 | H39: =$B$9 -> 5800 | I39: =$B$9 -> 5800 | ... M39: =$B$9 -> 5800 | O39: =SUM(B39:M39) -> 69600 | P39: =IF(O26=0,0,O39/O26) -> 0.092063492
A40: Utilities | B40: =$B$10*B$18 -> 1265 | C40: =$B$10*C$18 -> 1265 | D40: =$B$10*D$18 -> 1100 | E40: =$B$10*E$18 -> 990 | F40: =$B$10*F$18 -> 1045 | G40: =$B$10*G$18 -> 1155 | H40: =$B$10*H$18 -> 1298 | I40: =$B$10*I$18 -> 1298 | ... M40: =$B$10*M$18 -> 1210 | O40: =SUM(B40:M40) -> 13761 | P40: =IF(O26=0,0,O40/O26) -> 0.018202381
A41: Marketing | B41: =B26*$B$11 -> 2520 | C41: =C26*$B$11 -> 2822.4 | D41: =D26*$B$11 -> 2066.4 | E41: =E26*$B$11 -> 2142 | F41: =F26*$B$11 -> 2721.6 | G41: =G26*$B$11 -> 2973.6 | H41: =H26*$B$11 -> 3074.4 | I41: =I26*$B$11 -> 2898 | ... M41: =M26*$B$11 -> 2091.6 | O41: =SUM(B41:M41) -> 30240 | P41: =IF(O26=0,0,O41/O26) -> 0.04
A42: Misc / Other | B42: =$B$12 -> 400 | C42: =$B$12 -> 400 | D42: =$B$12 -> 400 | E42: =$B$12 -> 400 | F42: =$B$12 -> 400 | G42: =$B$12 -> 400 | H42: =$B$12 -> 400 | I42: =$B$12 -> 400 | ... M42: =$B$12 -> 400 | O42: =SUM(B42:M42) -> 4800 | P42: =IF(O26=0,0,O42/O26) -> 0.0063492063
A43: Total OpEx | B43: =B37+B38+B39+B40+B41+B42 -> 27345 | C43: =C37+C38+C39+C40+C41+C42 -> 29310.6 | D43: =D37+D38+D39+D40+D41+D42 -> 24231.6 | E43: =E37+E38+E39+E40+E41+E42 -> 24613 | F43: =F37+F38+F39+F40+F41+F42 -> 28435.4 | G43: =G37+G38+G39+G40+G41+G42 -> 30183.4 | H43: =H37+H38+H39+H40+H41+H42 -> 30981.6 | I43: =I37+I38+I39+I40+I41+I42 -> 29835 | ... M43: =M37+M38+M39+M40+M41+M42 -> 24505.4 | O43: =SUM(B43:M43) -> 326721 | P43: =IF(O26=0,0,O43/O26) -> 0.43217063
A45: NET OPERATING INCOME (EBITDA) | B45: =B33-B43 -> 17385 | C45: =C33-C43 -> 20787 | D45: =D33-D43 -> 12447 | E45: =E33-E43 -> 13407.5 | F45: =F33-F43 -> 19192.6 | G45: =G33-G43 -> 21854.6 | H45: =H33-H43 -> 22436.1 | I45: =I33-I43 -> 20880 | ... M45: =M33-M43 -> 12620.5 | O45: =SUM(B45:M45) -> 206737.8 | P45: =IF(O26=0,0,O45/O26) -> 0.2734627
A46: NOI Margin % | B46: =IF(B26=0,0,B45/B26) -> 0.27595238 | C46: =IF(C26=0,0,C45/C26) -> 0.29460034 | D46: =IF(D26=0,0,D45/D26) -> 0.24094077 | E46: =IF(E26=0,0,E45/E26) -> 0.25037348 | F46: =IF(F26=0,0,F45/F26) -> 0.28207819 | G46: =IF(G26=0,0,G45/G26) -> 0.29398171 | H46: =IF(H26=0,0,H45/H26) -> 0.29190867 | I46: =IF(I26=0,0,I45/I26) -> 0.28819876 | ... M46: =IF(M26=0,0,M45/M26) -> 0.2413559 | O46: =IF(O26=0,0,O45/O26) -> 0.2734627 | P46: =IF(O26=0,0,O45/O26) -> 0.2734627

Sheet Little Caesars Location 3
A1: Little Caesars — Location 3 | Monthly P&L
A2: Blue = Editable Input | Black = Formula | Green = Linked | Yellow = Assumption cell | Amber = Seasonal index
A3: ASSUMPTIONS
A4: Monthly Base Revenue ($) | B4: 58000
A5: Food & Beverage Cost — Base (%) | B5: 0.27
A6: Paper & Supplies (%) | B6: 0.02
A7: Variable Labor (% of Revenue) | B7: 0.22
A8: Fixed Labor — Mgmt / Base Crew ($) | B8: 3500
A9: Monthly Rent ($) | B9: 5500
A10: Utilities — Base ($/mo) | B10: 1100
A11: Marketing (% of Revenue) | B11: 0.04
A12: Misc / Other ($/mo) | B12: 400
A14: MONTHLY SEASONAL INDICES (edit to model scenarios)
B15: Jan | C15: Feb | D15: Mar | E15: Apr | F15: May | G15: Jun | H15: Jul | I15: Aug | J15: Sep | K15: Oct | L15: Nov | M15: Dec | O15: Full Yr Avg | P15: Notes
A16: Revenue Index | B16: 1 | C16: 1.12 | D16: 0.82 | E16: 0.85 | F16: 1.08 | G16: 1.18 | H16: 1.22 | I16: 1.15 | J16: 0.88 | K16: 1.05 | L16: 0.82 | M16: 0.83 | O16: =AVERAGE(B16:M16) -> 1 | P16: 1.00=avg month. >1.00=above avg revenue.
A17: Food Cost Adj (%) | B17: 0 | C17: 0 | D17: 0 | E17: 0 | F17: 0.01 | G17: 0.01 | H17: 0.015 | I17: 0.01 | J17: 0 | K17: 0 | L17: 0 | M17: 0 | O17: =AVERAGE(B17:M17) -> 0.00375 | P17: Added to base food %. Commodity/demand swings.
A18: Utility Seasonal Factor | B18: 1.15 | C18: 1.15 | D18: 1 | E18: 0.9 | F18: 0.95 | G18: 1.05 | H18: 1.18 | I18: 1.18 | J18: 0.95 | K18: 0.9 | L18: 1 | M18: 1.1 | O18: =AVERAGE(B18:M18) -> 1.0425 | P18: Multiplied by base utility $. Weather-driven.
A20: MONTHLY PROFIT & LOSS
A21: Line Item | B21: Jan | C21: Feb | D21: Mar | E21: Apr | F21: May | G21: Jun | H21: Jul | I21: Aug | J21: Sep | K21: Oct | L21: Nov | M21: Dec | N21: Full Year | O21: % of Rev
A22: REVENUE
A23: In-Store / Counter | B23: =$B$4*B$16*0.35 -> 20300 | C23: =$B$4*C$16*0.35 -> 22736 | D23: =$B$4*D$16*0.35 -> 16646 | E23: =$B$4*E$16*0.35 -> 17255 | F23: =$B$4*F$16*0.35 -> 21924 | G23: =$B$4*G$16*0.35 -> 23954 | H23: =$B$4*H$16*0.35 -> 24766 | I23: =$B$4*I$16*0.35 -> 23345 | ... M23: =$B$4*M$16*0.35 -> 16849 | O23: =SUM(B23:M23) -> 243600 | P23: =IF(O26=0,0,O23/O26) -> 0.35
A24: Delivery / Pickup | B24: =$B$4*B$16*0.55 -> 31900 | C24: =$B$4*C$16*0.55 -> 35728 | D24: =$B$4*D$16*0.55 -> 26158 | E24: =$B$4*E$16*0.55 -> 27115 | F24: =$B$4*F$16*0.55 -> 34452 | G24: =$B$4*G$16*0.55 -> 37642 | H24: =$B$4*H$16*0.55 -> 38918 | I24: =$B$4*I$16*0.55 -> 36685 | ... M24: =$B$4*M$16*0.55 -> 26477 | O24: =SUM(B24:M24) -> 382800 | P24: =IF(O26=0,0,O24/O26) -> 0.55
A25: Catering / Online | B25: =$B$4*B$16*0.1 -> 5800 | C25: =$B$4*C$16*0.1 -> 6496 | D25: =$B$4*D$16*0.1 -> 4756 | E25: =$B$4*E$16*0.1 -> 4930 | F25: =$B$4*F$16*0.1 -> 6264 | G25: =$B$4*G$16*0.1 -> 6844 | H25: =$B$4*H$16*0.1 -> 7076 | I25: =$B$4*I$16*0.1 -> 6670 | ... M25: =$B$4*M$16*0.1 -> 4814 | O25: =SUM(B25:M25) -> 69600 | P25: =IF(O26=0,0,O25/O26) -> 0.1
A26: Total Revenue | B26: =B23+B24+B25 -> 58000 | C26: =C23+C24+C25 -> 64960 | D26: =D23+D24+D25 -> 47560 | E26: =E23+E24+E25 -> 49300 | F26: =F23+F24+F25 -> 62640 | G26: =G23+G24+G25 -> 68440 | H26: =H23+H24+H25 -> 70760 | I26: =I23+I24+I25 -> 66700 | ... M26: =M23+M24+M25 -> 48140 | O26: =SUM(B26:M26) -> 696000 | P26: =IF(O26=0,0,O26/O26) -> 1
A28: COST OF GOODS SOLD
A29: Food & Beverage Cost | B29: =B26*($B$5+B$17) -> 15660 | C29: =C26*($B$5+C$17) -> 17539.2 | D29: =D26*($B$5+D$17) -> 12841.2 | E29: =E26*($B$5+E$17) -> 13311 | F29: =F26*($B$5+F$17) -> 17539.2 | G29: =G26*($B$5+G$17) -> 19163.2 | H29: =H26*($B$5+H$17) -> 20166.6 | I29: =I26*($B$5+I$17) -> 18676 | ... M29: =M26*($B$5+M$17) -> 12997.8 | O29: =SUM(B29:M29) -> 190959.2 | P29: =IF(O26=0,0,O29/O26) -> 0.27436667
A30: Paper & Supplies | B30: =B26*$B$6 -> 1160 | C30: =C26*$B$6 -> 1299.2 | D30: =D26*$B$6 -> 951.2 | E30: =E26*$B$6 -> 986 | F30: =F26*$B$6 -> 1252.8 | G30: =G26*$B$6 -> 1368.8 | H30: =H26*$B$6 -> 1415.2 | I30: =I26*$B$6 -> 1334 | ... M30: =M26*$B$6 -> 962.8 | O30: =SUM(B30:M30) -> 13920 | P30: =IF(O26=0,0,O30/O26) -> 0.02
A31: Total COGS | B31: =B29+B30 -> 16820 | C31: =C29+C30 -> 18838.4 | D31: =D29+D30 -> 13792.4 | E31: =E29+E30 -> 14297 | F31: =F29+F30 -> 18792 | G31: =G29+G30 -> 20532 | H31: =H29+H30 -> 21581.8 | I31: =I29+I30 -> 20010 | ... M31: =M29+M30 -> 13960.6 | O31: =SUM(B31:M31) -> 204879.2 | P31: =IF(O26=0,0,O31/O26) -> 0.29436667
A33: GROSS PROFIT | B33: =B26-B31 -> 41180 | C33: =C26-C31 -> 46121.6 | D33: =D26-D31 -> 33767.6 | E33: =E26-E31 -> 35003 | F33: =F26-F31 -> 43848 | G33: =G26-G31 -> 47908 | H33: =H26-H31 -> 49178.2 | I33: =I26-I31 -> 46690 | ... M33: =M26-M31 -> 34179.4 | O33: =SUM(B33:M33) -> 491120.8 | P33: =IF(O26=0,0,O33/O26) -> 0.70563333
A34: Gross Margin % | B34: =IF(B26=0,0,B33/B26) -> 0.71 | C34: =IF(C26=0,0,C33/C26) -> 0.71 | D34: =IF(D26=0,0,D33/D26) -> 0.71 | E34: =IF(E26=0,0,E33/E26) -> 0.71 | F34: =IF(F26=0,0,F33/F26) -> 0.7 | G34: =IF(G26=0,0,G33/G26) -> 0.7 | H34: =IF(H26=0,0,H33/H26) -> 0.695 | I34: =IF(I26=0,0,I33/I26) -> 0.7 | ... M34: =IF(M26=0,0,M33/M26) -> 0.71 | O34: =IF(O26=0,0,O33/O26) -> 0.70563333 | P34: =IF(O26=0,0,O33/O26) -> 0.70563333
A36: OPERATING EXPENSES
A37: Variable Labor | B37: =B26*$B$7 -> 12760 | C37: =C26*$B$7 -> 14291.2 | D37: =D26*$B$7 -> 10463.2 | E37: =E26*$B$7 -> 10846 | F37: =F26*$B$7 -> 13780.8 | G37: =G26*$B$7 -> 15056.8 | H37: =H26*$B$7 -> 15567.2 | I37: =I26*$B$7 -> 14674 | ... M37: =M26*$B$7 -> 10590.8 | O37: =SUM(B37:M37) -> 153120 | P37: =IF(O26=0,0,O37/O26) -> 0.22
A38: Fixed Labor (Mgmt / Base Crew) | B38: =$B$8 -> 3500 | C38: =$B$8 -> 3500 | D38: =$B$8 -> 3500 | E38: =$B$8 -> 3500 | F38: =$B$8 -> 3500 | G38: =$B$8 -> 3500 | H38: =$B$8 -> 3500 | I38: =$B$8 -> 3500 | ... M38: =$B$8 -> 3500 | O38: =SUM(B38:M38) -> 42000 | P38: =IF(O26=0,0,O38/O26) -> 0.060344828
A39: Rent | B39: =$B$9 -> 5500 | C39: =$B$9 -> 5500 | D39: =$B$9 -> 5500 | E39: =$B$9 -> 5500 | F39: =$B$9 -> 5500 | G39: =$B$9 -> 5500 | H39: =$B$9 -> 5500 | I39: =$B$9 -> 5500 | ... M39: =$B$9 -> 5500 | O39: =SUM(B39:M39) -> 66000 | P39: =IF(O26=0,0,O39/O26) -> 0.094827586
A40: Utilities | B40: =$B$10*B$18 -> 1265 | C40: =$B$10*C$18 -> 1265 | D40: =$B$10*D$18 -> 1100 | E40: =$B$10*E$18 -> 990 | F40: =$B$10*F$18 -> 1045 | G40: =$B$10*G$18 -> 1155 | H40: =$B$10*H$18 -> 1298 | I40: =$B$10*I$18 -> 1298 | ... M40: =$B$10*M$18 -> 1210 | O40: =SUM(B40:M40) -> 13761 | P40: =IF(O26=0,0,O40/O26) -> 0.019771552
A41: Marketing | B41: =B26*$B$11 -> 2320 | C41: =C26*$B$11 -> 2598.4 | D41: =D26*$B$11 -> 1902.4 | E41: =E26*$B$11 -> 1972 | F41: =F26*$B$11 -> 2505.6 | G41: =G26*$B$11 -> 2737.6 | H41: =H26*$B$11 -> 2830.4 | I41: =I26*$B$11 -> 2668 | ... M41: =M26*$B$11 -> 1925.6 | O41: =SUM(B41:M41) -> 27840 | P41: =IF(O26=0,0,O41/O26) -> 0.04
A42: Misc / Other | B42: =$B$12 -> 400 | C42: =$B$12 -> 400 | D42: =$B$12 -> 400 | E42: =$B$12 -> 400 | F42: =$B$12 -> 400 | G42: =$B$12 -> 400 | H42: =$B$12 -> 400 | I42: =$B$12 -> 400 | ... M42: =$B$12 -> 400 | O42: =SUM(B42:M42) -> 4800 | P42: =IF(O26=0,0,O42/O26) -> 0.0068965517
A43: Total OpEx | B43: =B37+B38+B39+B40+B41+B42 -> 25745 | C43: =C37+C38+C39+C40+C41+C42 -> 27554.6 | D43: =D37+D38+D39+D40+D41+D42 -> 22865.6 | E43: =E37+E38+E39+E40+E41+E42 -> 23208 | F43: =F37+F38+F39+F40+F41+F42 -> 26731.4 | G43: =G37+G38+G39+G40+G41+G42 -> 28349.4 | H43: =H37+H38+H39+H40+H41+H42 -> 29095.6 | I43: =I37+I38+I39+I40+I41+I42 -> 28040 | ... M43: =M37+M38+M39+M40+M41+M42 -> 23126.4 | O43: =SUM(B43:M43) -> 307521 | P43: =IF(O26=0,0,O43/O26) -> 0.44184052
A45: NET OPERATING INCOME (EBITDA) | B45: =B33-B43 -> 15435 | C45: =C33-C43 -> 18567 | D45: =D33-D43 -> 10902 | E45: =E33-E43 -> 11795 | F45: =F33-F43 -> 17116.6 | G45: =G33-G43 -> 19558.6 | H45: =H33-H43 -> 20082.6 | I45: =I33-I43 -> 18650 | ... M45: =M33-M43 -> 11053 | O45: =SUM(B45:M45) -> 183599.8 | P45: =IF(O26=0,0,O45/O26) -> 0.26379282
A46: NOI Margin % | B46: =IF(B26=0,0,B45/B26) -> 0.26612069 | C46: =IF(C26=0,0,C45/C26) -> 0.28582204 | D46: =IF(D26=0,0,D45/D26) -> 0.22922624 | E46: =IF(E26=0,0,E45/E26) -> 0.23924949 | F46: =IF(F26=0,0,F45/F26) -> 0.27325351 | G46: =IF(G26=0,0,G45/G26) -> 0.28577732 | H46: =IF(H26=0,0,H45/H26) -> 0.28381289 | I46: =IF(I26=0,0,I45/I26) -> 0.27961019 | ... M46: =IF(M26=0,0,M45/M26) -> 0.22960116 | O46: =IF(O26=0,0,O45/O26) -> 0.26379282 | P46: =IF(O26=0,0,O45/O26) -> 0.26379282

Sheet Little Caesars Location 4
A1: Little Caesars — Location 4 | Monthly P&L
A2: Blue = Editable Input | Black = Formula | Green = Linked | Yellow = Assumption cell | Amber = Seasonal index
A3: ASSUMPTIONS
A4: Monthly Base Revenue ($) | B4: 62000
A5: Food & Beverage Cost — Base (%) | B5: 0.27
A6: Paper & Supplies (%) | B6: 0.02
A7: Variable Labor (% of Revenue) | B7: 0.22
A8: Fixed Labor — Mgmt / Base Crew ($) | B8: 3500
A9: Monthly Rent ($) | B9: 6000
A10: Utilities — Base ($/mo) | B10: 1100
A11: Marketing (% of Revenue) | B11: 0.04
A12: Misc / Other ($/mo) | B12: 400
A14: MONTHLY SEASONAL INDICES (edit to model scenarios)
B15: Jan | C15: Feb | D15: Mar | E15: Apr | F15: May | G15: Jun | H15: Jul | I15: Aug | J15: Sep | K15: Oct | L15: Nov | M15: Dec | O15: Full Yr Avg | P15: Notes
A16: Revenue Index | B16: 1 | C16: 1.12 | D16: 0.82 | E16: 0.85 | F16: 1.08 | G16: 1.18 | H16: 1.22 | I16: 1.15 | J16: 0.88 | K16: 1.05 | L16: 0.82 | M16: 0.83 | O16: =AVERAGE(B16:M16) -> 1 | P16: 1.00=avg month. >1.00=above avg revenue.
A17: Food Cost Adj (%) | B17: 0 | C17: 0 | D17: 0 | E17: 0 | F17: 0.01 | G17: 0.01 | H17: 0.015 | I17: 0.01 | J17: 0 | K17: 0 | L17: 0 | M17: 0 | O17: =AVERAGE(B17:M17) -> 0.00375 | P17: Added to base food %. Commodity/demand swings.
A18: Utility Seasonal Factor | B18: 1.15 | C18: 1.15 | D18: 1 | E18: 0.9 | F18: 0.95 | G18: 1.05 | H18: 1.18 | I18: 1.18 | J18: 0.95 | K18: 0.9 | L18: 1 | M18: 1.1 | O18: =AVERAGE(B18:M18) -> 1.0425 | P18: Multiplied by base utility $. Weather-driven.
A20: MONTHLY PROFIT & LOSS
A21: Line Item | B21: Jan | C21: Feb | D21: Mar | E21: Apr | F21: May | G21: Jun | H21: Jul | I21: Aug | J21: Sep | K21: Oct | L21: Nov | M21: Dec | N21: Full Year | O21: % of Rev
A22: REVENUE
A23: In-Store / Counter | B23: =$B$4*B$16*0.35 -> 21700 | C23: =$B$4*C$16*0.35 -> 24304 | D23: =$B$4*D$16*0.35 -> 17794 | E23: =$B$4*E$16*0.35 -> 18445 | F23: =$B$4*F$16*0.35 -> 23436 | G23: =$B$4*G$16*0.35 -> 25606 | H23: =$B$4*H$16*0.35 -> 26474 | I23: =$B$4*I$16*0.35 -> 24955 | ... M23: =$B$4*M$16*0.35 -> 18011 | O23: =SUM(B23:M23) -> 260400 | P23: =IF(O26=0,0,O23/O26) -> 0.35
A24: Delivery / Pickup | B24: =$B$4*B$16*0.55 -> 34100 | C24: =$B$4*C$16*0.55 -> 38192 | D24: =$B$4*D$16*0.55 -> 27962 | E24: =$B$4*E$16*0.55 -> 28985 | F24: =$B$4*F$16*0.55 -> 36828 | G24: =$B$4*G$16*0.55 -> 40238 | H24: =$B$4*H$16*0.55 -> 41602 | I24: =$B$4*I$16*0.55 -> 39215 | ... M24: =$B$4*M$16*0.55 -> 28303 | O24: =SUM(B24:M24) -> 409200 | P24: =IF(O26=0,0,O24/O26) -> 0.55
A25: Catering / Online | B25: =$B$4*B$16*0.1 -> 6200 | C25: =$B$4*C$16*0.1 -> 6944 | D25: =$B$4*D$16*0.1 -> 5084 | E25: =$B$4*E$16*0.1 -> 5270 | F25: =$B$4*F$16*0.1 -> 6696 | G25: =$B$4*G$16*0.1 -> 7316 | H25: =$B$4*H$16*0.1 -> 7564 | I25: =$B$4*I$16*0.1 -> 7130 | ... M25: =$B$4*M$16*0.1 -> 5146 | O25: =SUM(B25:M25) -> 74400 | P25: =IF(O26=0,0,O25/O26) -> 0.1
A26: Total Revenue | B26: =B23+B24+B25 -> 62000 | C26: =C23+C24+C25 -> 69440 | D26: =D23+D24+D25 -> 50840 | E26: =E23+E24+E25 -> 52700 | F26: =F23+F24+F25 -> 66960 | G26: =G23+G24+G25 -> 73160 | H26: =H23+H24+H25 -> 75640 | I26: =I23+I24+I25 -> 71300 | ... M26: =M23+M24+M25 -> 51460 | O26: =SUM(B26:M26) -> 744000 | P26: =IF(O26=0,0,O26/O26) -> 1
A28: COST OF GOODS SOLD
A29: Food & Beverage Cost | B29: =B26*($B$5+B$17) -> 16740 | C29: =C26*($B$5+C$17) -> 18748.8 | D29: =D26*($B$5+D$17) -> 13726.8 | E29: =E26*($B$5+E$17) -> 14229 | F29: =F26*($B$5+F$17) -> 18748.8 | G29: =G26*($B$5+G$17) -> 20484.8 | H29: =H26*($B$5+H$17) -> 21557.4 | I29: =I26*($B$5+I$17) -> 19964 | ... M29: =M26*($B$5+M$17) -> 13894.2 | O29: =SUM(B29:M29) -> 204128.8 | P29: =IF(O26=0,0,O29/O26) -> 0.27436667
A30: Paper & Supplies | B30: =B26*$B$6 -> 1240 | C30: =C26*$B$6 -> 1388.8 | D30: =D26*$B$6 -> 1016.8 | E30: =E26*$B$6 -> 1054 | F30: =F26*$B$6 -> 1339.2 | G30: =G26*$B$6 -> 1463.2 | H30: =H26*$B$6 -> 1512.8 | I30: =I26*$B$6 -> 1426 | ... M30: =M26*$B$6 -> 1029.2 | O30: =SUM(B30:M30) -> 14880 | P30: =IF(O26=0,0,O30/O26) -> 0.02
A31: Total COGS | B31: =B29+B30 -> 17980 | C31: =C29+C30 -> 20137.6 | D31: =D29+D30 -> 14743.6 | E31: =E29+E30 -> 15283 | F31: =F29+F30 -> 20088 | G31: =G29+G30 -> 21948 | H31: =H29+H30 -> 23070.2 | I31: =I29+I30 -> 21390 | ... M31: =M29+M30 -> 14923.4 | O31: =SUM(B31:M31) -> 219008.8 | P31: =IF(O26=0,0,O31/O26) -> 0.29436667
A33: GROSS PROFIT | B33: =B26-B31 -> 44020 | C33: =C26-C31 -> 49302.4 | D33: =D26-D31 -> 36096.4 | E33: =E26-E31 -> 37417 | F33: =F26-F31 -> 46872 | G33: =G26-G31 -> 51212 | H33: =H26-H31 -> 52569.8 | I33: =I26-I31 -> 49910 | ... M33: =M26-M31 -> 36536.6 | O33: =SUM(B33:M33) -> 524991.2 | P33: =IF(O26=0,0,O33/O26) -> 0.70563333
A34: Gross Margin % | B34: =IF(B26=0,0,B33/B26) -> 0.71 | C34: =IF(C26=0,0,C33/C26) -> 0.71 | D34: =IF(D26=0,0,D33/D26) -> 0.71 | E34: =IF(E26=0,0,E33/E26) -> 0.71 | F34: =IF(F26=0,0,F33/F26) -> 0.7 | G34: =IF(G26=0,0,G33/G26) -> 0.7 | H34: =IF(H26=0,0,H33/H26) -> 0.695 | I34: =IF(I26=0,0,I33/I26) -> 0.7 | ... M34: =IF(M26=0,0,M33/M26) -> 0.71 | O34: =IF(O26=0,0,O33/O26) -> 0.70563333 | P34: =IF(O26=0,0,O33/O26) -> 0.70563333
A36: OPERATING EXPENSES
A37: Variable Labor | B37: =B26*$B$7 -> 13640 | C37: =C26*$B$7 -> 15276.8 | D37: =D26*$B$7 -> 11184.8 | E37: =E26*$B$7 -> 11594 | F37: =F26*$B$7 -> 14731.2 | G37: =G26*$B$7 -> 16095.2 | H37: =H26*$B$7 -> 16640.8 | I37: =I26*$B$7 -> 15686 | ... M37: =M26*$B$7 -> 11321.2 | O37: =SUM(B37:M37) -> 163680 | P37: =IF(O26=0,0,O37/O26) -> 0.22
A38: Fixed Labor (Mgmt / Base Crew) | B38: =$B$8 -> 3500 | C38: =$B$8 -> 3500 | D38: =$B$8 -> 3500 | E38: =$B$8 -> 3500 | F38: =$B$8 -> 3500 | G38: =$B$8 -> 3500 | H38: =$B$8 -> 3500 | I38: =$B$8 -> 3500 | ... M38: =$B$8 -> 3500 | O38: =SUM(B38:M38) -> 42000 | P38: =IF(O26=0,0,O38/O26) -> 0.056451613
A39: Rent | B39: =$B$9 -> 6000 | C39: =$B$9 -> 6000 | D39: =$B$9 -> 6000 | E39: =$B$9 -> 6000 | F39: =$B$9 -> 6000 | G39: =$B$9 -> 6000 | H39: =$B$9 -> 6000 | I39: =$B$9 -> 6000 | ... M39: =$B$9 -> 6000 | O39: =SUM(B39:M39) -> 72000 | P39: =IF(O26=0,0,O39/O26) -> 0.096774194
A40: Utilities | B40: =$B$10*B$18 -> 1265 | C40: =$B$10*C$18 -> 1265 | D40: =$B$10*D$18 -> 1100 | E40: =$B$10*E$18 -> 990 | F40: =$B$10*F$18 -> 1045 | G40: =$B$10*G$18 -> 1155 | H40: =$B$10*H$18 -> 1298 | I40: =$B$10*I$18 -> 1298 | ... M40: =$B$10*M$18 -> 1210 | O40: =SUM(B40:M40) -> 13761 | P40: =IF(O26=0,0,O40/O26) -> 0.018495968
A41: Marketing | B41: =B26*$B$11 -> 2480 | C41: =C26*$B$11 -> 2777.6 | D41: =D26*$B$11 -> 2033.6 | E41: =E26*$B$11 -> 2108 | F41: =F26*$B$11 -> 2678.4 | G41: =G26*$B$11 -> 2926.4 | H41: =H26*$B$11 -> 3025.6 | I41: =I26*$B$11 -> 2852 | ... M41: =M26*$B$11 -> 2058.4 | O41: =SUM(B41:M41) -> 29760 | P41: =IF(O26=0,0,O41/O26) -> 0.04
A42: Misc / Other | B42: =$B$12 -> 400 | C42: =$B$12 -> 400 | D42: =$B$12 -> 400 | E42: =$B$12 -> 400 | F42: =$B$12 -> 400 | G42: =$B$12 -> 400 | H42: =$B$12 -> 400 | I42: =$B$12 -> 400 | ... M42: =$B$12 -> 400 | O42: =SUM(B42:M42) -> 4800 | P42: =IF(O26=0,0,O42/O26) -> 0.0064516129
A43: Total OpEx | B43: =B37+B38+B39+B40+B41+B42 -> 27285 | C43: =C37+C38+C39+C40+C41+C42 -> 29219.4 | D43: =D37+D38+D39+D40+D41+D42 -> 24218.4 | E43: =E37+E38+E39+E40+E41+E42 -> 24592 | F43: =F37+F38+F39+F40+F41+F42 -> 28354.6 | G43: =G37+G38+G39+G40+G41+G42 -> 30076.6 | H43: =H37+H38+H39+H40+H41+H42 -> 30864.4 | I43: =I37+I38+I39+I40+I41+I42 -> 29736 | ... M43: =M37+M38+M39+M40+M41+M42 -> 24489.6 | O43: =SUM(B43:M43) -> 326001 | P43: =IF(O26=0,0,O43/O26) -> 0.43817339
A45: NET OPERATING INCOME (EBITDA) | B45: =B33-B43 -> 16735 | C45: =C33-C43 -> 20083 | D45: =D33-D43 -> 11878 | E45: =E33-E43 -> 12825 | F45: =F33-F43 -> 18517.4 | G45: =G33-G43 -> 21135.4 | H45: =H33-H43 -> 21705.4 | I45: =I33-I43 -> 20174 | ... M45: =M33-M43 -> 12047 | O45: =SUM(B45:M45) -> 198990.2 | P45: =IF(O26=0,0,O45/O26) -> 0.26745995
A46: NOI Margin % | B46: =IF(B26=0,0,B45/B26) -> 0.26991935 | C46: =IF(C26=0,0,C45/C26) -> 0.28921371 | D46: =IF(D26=0,0,D45/D26) -> 0.23363493 | E46: =IF(E26=0,0,E45/E26) -> 0.24335863 | F46: =IF(F26=0,0,F45/F26) -> 0.27654421 | G46: =IF(G26=0,0,G45/G26) -> 0.28889284 | H46: =IF(H26=0,0,H45/H26) -> 0.28695664 | I46: =IF(I26=0,0,I45/I26) -> 0.2829453 | ... M46: =IF(M26=0,0,M45/M26) -> 0.23410416 | O46: =IF(O26=0,0,O45/O26) -> 0.26745995 | P46: =IF(O26=0,0,O45/O26) -> 0.26745995

Sheet Arbys Location 1
A1: Arby's — Location 1 | Monthly P&L
A2: Blue = Editable Input | Black = Formula | Green = Linked | Yellow = Assumption cell | Amber = Seasonal index
A3: ASSUMPTIONS
A4: Monthly Base Revenue ($) | B4: 75000
A5: Food & Beverage Cost — Base (%) | B5: 0.3
A6: Paper & Supplies (%) | B6: 0.02
A7: Variable Labor (% of Revenue) | B7: 0.2
A8: Fixed Labor — Mgmt / Base Crew ($) | B8: 4200
A9: Monthly Rent ($) | B9: 7800
A10: Utilities — Base ($/mo) | B10: 1400
A11: Marketing (% of Revenue) | B11: 0.03
A12: Misc / Other ($/mo) | B12: 550
A14: MONTHLY SEASONAL INDICES (edit to model scenarios)
B15: Jan | C15: Feb | D15: Mar | E15: Apr | F15: May | G15: Jun | H15: Jul | I15: Aug | J15: Sep | K15: Oct | L15: Nov | M15: Dec | O15: Full Yr Avg | P15: Notes
A16: Revenue Index | B16: 0.98 | C16: 1.02 | D16: 1.02 | E16: 1 | F16: 1.02 | G16: 1 | H16: 0.97 | I16: 0.98 | J16: 1 | K16: 1.01 | L16: 1 | M16: 1 | O16: =AVERAGE(B16:M16) -> 1 | P16: 1.00=avg month. >1.00=above avg revenue.
A17: Food Cost Adj (%) | B17: 0 | C17: 0 | D17: 0 | E17: 0 | F17: 0 | G17: 0.005 | H17: 0.008 | I17: 0.005 | J17: 0 | K17: 0 | L17: 0 | M17: 0 | O17: =AVERAGE(B17:M17) -> 0.0015 | P17: Added to base food %. Commodity/demand swings.
A18: Utility Seasonal Factor | B18: 1.15 | C18: 1.15 | D18: 1 | E18: 0.9 | F18: 0.95 | G18: 1.05 | H18: 1.18 | I18: 1.18 | J18: 0.95 | K18: 0.9 | L18: 1 | M18: 1.1 | O18: =AVERAGE(B18:M18) -> 1.0425 | P18: Multiplied by base utility $. Weather-driven.
A20: MONTHLY PROFIT & LOSS
A21: Line Item | B21: Jan | C21: Feb | D21: Mar | E21: Apr | F21: May | G21: Jun | H21: Jul | I21: Aug | J21: Sep | K21: Oct | L21: Nov | M21: Dec | N21: Full Year | O21: % of Rev
A22: REVENUE
A23: Drive-Thru / Dine-In | B23: =$B$4*B$16*0.7 -> 51450 | C23: =$B$4*C$16*0.7 -> 53550 | D23: =$B$4*D$16*0.7 -> 53550 | E23: =$B$4*E$16*0.7 -> 52500 | F23: =$B$4*F$16*0.7 -> 53550 | G23: =$B$4*G$16*0.7 -> 52500 | H23: =$B$4*H$16*0.7 -> 50925 | I23: =$B$4*I$16*0.7 -> 51450 | ... M23: =$B$4*M$16*0.7 -> 52500 | O23: =SUM(B23:M23) -> 630000 | P23: =IF(O26=0,0,O23/O26) -> 0.7
A24: Delivery / App Orders | B24: =$B$4*B$16*0.25 -> 18375 | C24: =$B$4*C$16*0.25 -> 19125 | D24: =$B$4*D$16*0.25 -> 19125 | E24: =$B$4*E$16*0.25 -> 18750 | F24: =$B$4*F$16*0.25 -> 19125 | G24: =$B$4*G$16*0.25 -> 18750 | H24: =$B$4*H$16*0.25 -> 18187.5 | I24: =$B$4*I$16*0.25 -> 18375 | ... M24: =$B$4*M$16*0.25 -> 18750 | O24: =SUM(B24:M24) -> 225000 | P24: =IF(O26=0,0,O24/O26) -> 0.25
A25: Catering | B25: =$B$4*B$16*0.05 -> 3675 | C25: =$B$4*C$16*0.05 -> 3825 | D25: =$B$4*D$16*0.05 -> 3825 | E25: =$B$4*E$16*0.05 -> 3750 | F25: =$B$4*F$16*0.05 -> 3825 | G25: =$B$4*G$16*0.05 -> 3750 | H25: =$B$4*H$16*0.05 -> 3637.5 | I25: =$B$4*I$16*0.05 -> 3675 | ... M25: =$B$4*M$16*0.05 -> 3750 | O25: =SUM(B25:M25) -> 45000 | P25: =IF(O26=0,0,O25/O26) -> 0.05
A26: Total Revenue | B26: =B23+B24+B25 -> 73500 | C26: =C23+C24+C25 -> 76500 | D26: =D23+D24+D25 -> 76500 | E26: =E23+E24+E25 -> 75000 | F26: =F23+F24+F25 -> 76500 | G26: =G23+G24+G25 -> 75000 | H26: =H23+H24+H25 -> 72750 | I26: =I23+I24+I25 -> 73500 | ... M26: =M23+M24+M25 -> 75000 | O26: =SUM(B26:M26) -> 900000 | P26: =IF(O26=0,0,O26/O26) -> 1
A28: COST OF GOODS SOLD
A29: Food & Beverage Cost | B29: =B26*($B$5+B$17) -> 22050 | C29: =C26*($B$5+C$17) -> 22950 | D29: =D26*($B$5+D$17) -> 22950 | E29: =E26*($B$5+E$17) -> 22500 | F29: =F26*($B$5+F$17) -> 22950 | G29: =G26*($B$5+G$17) -> 22875 | H29: =H26*($B$5+H$17) -> 22407 | I29: =I26*($B$5+I$17) -> 22417.5 | ... M29: =M26*($B$5+M$17) -> 22500 | O29: =SUM(B29:M29) -> 271324.5 | P29: =IF(O26=0,0,O29/O26) -> 0.30147167
A30: Paper & Supplies | B30: =B26*$B$6 -> 1470 | C30: =C26*$B$6 -> 1530 | D30: =D26*$B$6 -> 1530 | E30: =E26*$B$6 -> 1500 | F30: =F26*$B$6 -> 1530 | G30: =G26*$B$6 -> 1500 | H30: =H26*$B$6 -> 1455 | I30: =I26*$B$6 -> 1470 | ... M30: =M26*$B$6 -> 1500 | O30: =SUM(B30:M30) -> 18000 | P30: =IF(O26=0,0,O30/O26) -> 0.02
A31: Total COGS | B31: =B29+B30 -> 23520 | C31: =C29+C30 -> 24480 | D31: =D29+D30 -> 24480 | E31: =E29+E30 -> 24000 | F31: =F29+F30 -> 24480 | G31: =G29+G30 -> 24375 | H31: =H29+H30 -> 23862 | I31: =I29+I30 -> 23887.5 | ... M31: =M29+M30 -> 24000 | O31: =SUM(B31:M31) -> 289324.5 | P31: =IF(O26=0,0,O31/O26) -> 0.32147167
A33: GROSS PROFIT | B33: =B26-B31 -> 49980 | C33: =C26-C31 -> 52020 | D33: =D26-D31 -> 52020 | E33: =E26-E31 -> 51000 | F33: =F26-F31 -> 52020 | G33: =G26-G31 -> 50625 | H33: =H26-H31 -> 48888 | I33: =I26-I31 -> 49612.5 | ... M33: =M26-M31 -> 51000 | O33: =SUM(B33:M33) -> 610675.5 | P33: =IF(O26=0,0,O33/O26) -> 0.67852833
A34: Gross Margin % | B34: =IF(B26=0,0,B33/B26) -> 0.68 | C34: =IF(C26=0,0,C33/C26) -> 0.68 | D34: =IF(D26=0,0,D33/D26) -> 0.68 | E34: =IF(E26=0,0,E33/E26) -> 0.68 | F34: =IF(F26=0,0,F33/F26) -> 0.68 | G34: =IF(G26=0,0,G33/G26) -> 0.675 | H34: =IF(H26=0,0,H33/H26) -> 0.672 | I34: =IF(I26=0,0,I33/I26) -> 0.675 | ... M34: =IF(M26=0,0,M33/M26) -> 0.68 | O34: =IF(O26=0,0,O33/O26) -> 0.67852833 | P34: =IF(O26=0,0,O33/O26) -> 0.67852833
A36: OPERATING EXPENSES
A37: Variable Labor | B37: =B26*$B$7 -> 14700 | C37: =C26*$B$7 -> 15300 | D37: =D26*$B$7 -> 15300 | E37: =E26*$B$7 -> 15000 | F37: =F26*$B$7 -> 15300 | G37: =G26*$B$7 -> 15000 | H37: =H26*$B$7 -> 14550 | I37: =I26*$B$7 -> 14700 | ... M37: =M26*$B$7 -> 15000 | O37: =SUM(B37:M37) -> 180000 | P37: =IF(O26=0,0,O37/O26) -> 0.2
A38: Fixed Labor (Mgmt / Base Crew) | B38: =$B$8 -> 4200 | C38: =$B$8 -> 4200 | D38: =$B$8 -> 4200 | E38: =$B$8 -> 4200 | F38: =$B$8 -> 4200 | G38: =$B$8 -> 4200 | H38: =$B$8 -> 4200 | I38: =$B$8 -> 4200 | ... M38: =$B$8 -> 4200 | O38: =SUM(B38:M38) -> 50400 | P38: =IF(O26=0,0,O38/O26) -> 0.056
A39: Rent | B39: =$B$9 -> 7800 | C39: =$B$9 -> 7800 | D39: =$B$9 -> 7800 | E39: =$B$9 -> 7800 | F39: =$B$9 -> 7800 | G39: =$B$9 -> 7800 | H39: =$B$9 -> 7800 | I39: =$B$9 -> 7800 | ... M39: =$B$9 -> 7800 | O39: =SUM(B39:M39) -> 93600 | P39: =IF(O26=0,0,O39/O26) -> 0.104
A40: Utilities | B40: =$B$10*B$18 -> 1610 | C40: =$B$10*C$18 -> 1610 | D40: =$B$10*D$18 -> 1400 | E40: =$B$10*E$18 -> 1260 | F40: =$B$10*F$18 -> 1330 | G40: =$B$10*G$18 -> 1470 | H40: =$B$10*H$18 -> 1652 | I40: =$B$10*I$18 -> 1652 | ... M40: =$B$10*M$18 -> 1540 | O40: =SUM(B40:M40) -> 17514 | P40: =IF(O26=0,0,O40/O26) -> 0.01946
A41: Marketing | B41: =B26*$B$11 -> 2205 | C41: =C26*$B$11 -> 2295 | D41: =D26*$B$11 -> 2295 | E41: =E26*$B$11 -> 2250 | F41: =F26*$B$11 -> 2295 | G41: =G26*$B$11 -> 2250 | H41: =H26*$B$11 -> 2182.5 | I41: =I26*$B$11 -> 2205 | ... M41: =M26*$B$11 -> 2250 | O41: =SUM(B41:M41) -> 27000 | P41: =IF(O26=0,0,O41/O26) -> 0.03
A42: Misc / Other | B42: =$B$12 -> 550 | C42: =$B$12 -> 550 | D42: =$B$12 -> 550 | E42: =$B$12 -> 550 | F42: =$B$12 -> 550 | G42: =$B$12 -> 550 | H42: =$B$12 -> 550 | I42: =$B$12 -> 550 | ... M42: =$B$12 -> 550 | O42: =SUM(B42:M42) -> 6600 | P42: =IF(O26=0,0,O42/O26) -> 0.0073333333
A43: Total OpEx | B43: =B37+B38+B39+B40+B41+B42 -> 31065 | C43: =C37+C38+C39+C40+C41+C42 -> 31755 | D43: =D37+D38+D39+D40+D41+D42 -> 31545 | E43: =E37+E38+E39+E40+E41+E42 -> 31060 | F43: =F37+F38+F39+F40+F41+F42 -> 31475 | G43: =G37+G38+G39+G40+G41+G42 -> 31270 | H43: =H37+H38+H39+H40+H41+H42 -> 30934.5 | I43: =I37+I38+I39+I40+I41+I42 -> 31107 | ... M43: =M37+M38+M39+M40+M41+M42 -> 31340 | O43: =SUM(B43:M43) -> 375114 | P43: =IF(O26=0,0,O43/O26) -> 0.41679333
A45: NET OPERATING INCOME (EBITDA) | B45: =B33-B43 -> 18915 | C45: =C33-C43 -> 20265 | D45: =D33-D43 -> 20475 | E45: =E33-E43 -> 19940 | F45: =F33-F43 -> 20545 | G45: =G33-G43 -> 19355 | H45: =H33-H43 -> 17953.5 | I45: =I33-I43 -> 18505.5 | ... M45: =M33-M43 -> 19660 | O45: =SUM(B45:M45) -> 235561.5 | P45: =IF(O26=0,0,O45/O26) -> 0.261735
A46: NOI Margin % | B46: =IF(B26=0,0,B45/B26) -> 0.25734694 | C46: =IF(C26=0,0,C45/C26) -> 0.26490196 | D46: =IF(D26=0,0,D45/D26) -> 0.26764706 | E46: =IF(E26=0,0,E45/E26) -> 0.26586667 | F46: =IF(F26=0,0,F45/F26) -> 0.26856209 | G46: =IF(G26=0,0,G45/G26) -> 0.25806667 | H46: =IF(H26=0,0,H45/H26) -> 0.24678351 | I46: =IF(I26=0,0,I45/I26) -> 0.25177551 | ... M46: =IF(M26=0,0,M45/M26) -> 0.26213333 | O46: =IF(O26=0,0,O45/O26) -> 0.261735 | P46: =IF(O26=0,0,O45/O26) -> 0.261735

Sheet Arbys Location 2
A1: Arby's — Location 2 | Monthly P&L
A2: Blue = Editable Input | Black = Formula | Green = Linked | Yellow = Assumption cell | Amber = Seasonal index
A3: ASSUMPTIONS
A4: Monthly Base Revenue ($) | B4: 72000
A5: Food & Beverage Cost — Base (%) | B5: 0.3
A6: Paper & Supplies (%) | B6: 0.02
A7: Variable Labor (% of Revenue) | B7: 0.2
A8: Fixed Labor — Mgmt / Base Crew ($) | B8: 4200
A9: Monthly Rent ($) | B9: 7500
A10: Utilities — Base ($/mo) | B10: 1400
A11: Marketing (% of Revenue) | B11: 0.03
A12: Misc / Other ($/mo) | B12: 550
A14: MONTHLY SEASONAL INDICES (edit to model scenarios)
B15: Jan | C15: Feb | D15: Mar | E15: Apr | F15: May | G15: Jun | H15: Jul | I15: Aug | J15: Sep | K15: Oct | L15: Nov | M15: Dec | O15: Full Yr Avg | P15: Notes
A16: Revenue Index | B16: 0.98 | C16: 1.02 | D16: 1.02 | E16: 1 | F16: 1.02 | G16: 1 | H16: 0.97 | I16: 0.98 | J16: 1 | K16: 1.01 | L16: 1 | M16: 1 | O16: =AVERAGE(B16:M16) -> 1 | P16: 1.00=avg month. >1.00=above avg revenue.
A17: Food Cost Adj (%) | B17: 0 | C17: 0 | D17: 0 | E17: 0 | F17: 0 | G17: 0.005 | H17: 0.008 | I17: 0.005 | J17: 0 | K17: 0 | L17: 0 | M17: 0 | O17: =AVERAGE(B17:M17) -> 0.0015 | P17: Added to base food %. Commodity/demand swings.
A18: Utility Seasonal Factor | B18: 1.15 | C18: 1.15 | D18: 1 | E18: 0.9 | F18: 0.95 | G18: 1.05 | H18: 1.18 | I18: 1.18 | J18: 0.95 | K18: 0.9 | L18: 1 | M18: 1.1 | O18: =AVERAGE(B18:M18) -> 1.0425 | P18: Multiplied by base utility $. Weather-driven.
A20: MONTHLY PROFIT & LOSS
A21: Line Item | B21: Jan | C21: Feb | D21: Mar | E21: Apr | F21: May | G21: Jun | H21: Jul | I21: Aug | J21: Sep | K21: Oct | L21: Nov | M21: Dec | N21: Full Year | O21: % of Rev
A22: REVENUE
A23: Drive-Thru / Dine-In | B23: =$B$4*B$16*0.7 -> 49392 | C23: =$B$4*C$16*0.7 -> 51408 | D23: =$B$4*D$16*0.7 -> 51408 | E23: =$B$4*E$16*0.7 -> 50400 | F23: =$B$4*F$16*0.7 -> 51408 | G23: =$B$4*G$16*0.7 -> 50400 | H23: =$B$4*H$16*0.7 -> 48888 | I23: =$B$4*I$16*0.7 -> 49392 | ... M23: =$B$4*M$16*0.7 -> 50400 | O23: =SUM(B23:M23) -> 604800 | P23: =IF(O26=0,0,O23/O26) -> 0.7
A24: Delivery / App Orders | B24: =$B$4*B$16*0.25 -> 17640 | C24: =$B$4*C$16*0.25 -> 18360 | D24: =$B$4*D$16*0.25 -> 18360 | E24: =$B$4*E$16*0.25 -> 18000 | F24: =$B$4*F$16*0.25 -> 18360 | G24: =$B$4*G$16*0.25 -> 18000 | H24: =$B$4*H$16*0.25 -> 17460 | I24: =$B$4*I$16*0.25 -> 17640 | ... M24: =$B$4*M$16*0.25 -> 18000 | O24: =SUM(B24:M24) -> 216000 | P24: =IF(O26=0,0,O24/O26) -> 0.25
A25: Catering | B25: =$B$4*B$16*0.05 -> 3528 | C25: =$B$4*C$16*0.05 -> 3672 | D25: =$B$4*D$16*0.05 -> 3672 | E25: =$B$4*E$16*0.05 -> 3600 | F25: =$B$4*F$16*0.05 -> 3672 | G25: =$B$4*G$16*0.05 -> 3600 | H25: =$B$4*H$16*0.05 -> 3492 | I25: =$B$4*I$16*0.05 -> 3528 | ... M25: =$B$4*M$16*0.05 -> 3600 | O25: =SUM(B25:M25) -> 43200 | P25: =IF(O26=0,0,O25/O26) -> 0.05
A26: Total Revenue | B26: =B23+B24+B25 -> 70560 | C26: =C23+C24+C25 -> 73440 | D26: =D23+D24+D25 -> 73440 | E26: =E23+E24+E25 -> 72000 | F26: =F23+F24+F25 -> 73440 | G26: =G23+G24+G25 -> 72000 | H26: =H23+H24+H25 -> 69840 | I26: =I23+I24+I25 -> 70560 | ... M26: =M23+M24+M25 -> 72000 | O26: =SUM(B26:M26) -> 864000 | P26: =IF(O26=0,0,O26/O26) -> 1
A28: COST OF GOODS SOLD
A29: Food & Beverage Cost | B29: =B26*($B$5+B$17) -> 21168 | C29: =C26*($B$5+C$17) -> 22032 | D29: =D26*($B$5+D$17) -> 22032 | E29: =E26*($B$5+E$17) -> 21600 | F29: =F26*($B$5+F$17) -> 22032 | G29: =G26*($B$5+G$17) -> 21960 | H29: =H26*($B$5+H$17) -> 21510.72 | I29: =I26*($B$5+I$17) -> 21520.8 | ... M29: =M26*($B$5+M$17) -> 21600 | O29: =SUM(B29:M29) -> 260471.52 | P29: =IF(O26=0,0,O29/O26) -> 0.30147167
A30: Paper & Supplies | B30: =B26*$B$6 -> 1411.2 | C30: =C26*$B$6 -> 1468.8 | D30: =D26*$B$6 -> 1468.8 | E30: =E26*$B$6 -> 1440 | F30: =F26*$B$6 -> 1468.8 | G30: =G26*$B$6 -> 1440 | H30: =H26*$B$6 -> 1396.8 | I30: =I26*$B$6 -> 1411.2 | ... M30: =M26*$B$6 -> 1440 | O30: =SUM(B30:M30) -> 17280 | P30: =IF(O26=0,0,O30/O26) -> 0.02
A31: Total COGS | B31: =B29+B30 -> 22579.2 | C31: =C29+C30 -> 23500.8 | D31: =D29+D30 -> 23500.8 | E31: =E29+E30 -> 23040 | F31: =F29+F30 -> 23500.8 | G31: =G29+G30 -> 23400 | H31: =H29+H30 -> 22907.52 | I31: =I29+I30 -> 22932 | ... M31: =M29+M30 -> 23040 | O31: =SUM(B31:M31) -> 277751.52 | P31: =IF(O26=0,0,O31/O26) -> 0.32147167
A33: GROSS PROFIT | B33: =B26-B31 -> 47980.8 | C33: =C26-C31 -> 49939.2 | D33: =D26-D31 -> 49939.2 | E33: =E26-E31 -> 48960 | F33: =F26-F31 -> 49939.2 | G33: =G26-G31 -> 48600 | H33: =H26-H31 -> 46932.48 | I33: =I26-I31 -> 47628 | ... M33: =M26-M31 -> 48960 | O33: =SUM(B33:M33) -> 586248.48 | P33: =IF(O26=0,0,O33/O26) -> 0.67852833
A34: Gross Margin % | B34: =IF(B26=0,0,B33/B26) -> 0.68 | C34: =IF(C26=0,0,C33/C26) -> 0.68 | D34: =IF(D26=0,0,D33/D26) -> 0.68 | E34: =IF(E26=0,0,E33/E26) -> 0.68 | F34: =IF(F26=0,0,F33/F26) -> 0.68 | G34: =IF(G26=0,0,G33/G26) -> 0.675 | H34: =IF(H26=0,0,H33/H26) -> 0.672 | I34: =IF(I26=0,0,I33/I26) -> 0.675 | ... M34: =IF(M26=0,0,M33/M26) -> 0.68 | O34: =IF(O26=0,0,O33/O26) -> 0.67852833 | P34: =IF(O26=0,0,O33/O26) -> 0.67852833
A36: OPERATING EXPENSES
A37: Variable Labor | B37: =B26*$B$7 -> 14112 | C37: =C26*$B$7 -> 14688 | D37: =D26*$B$7 -> 14688 | E37: =E26*$B$7 -> 14400 | F37: =F26*$B$7 -> 14688 | G37: =G26*$B$7 -> 14400 | H37: =H26*$B$7 -> 13968 | I37: =I26*$B$7 -> 14112 | ... M37: =M26*$B$7 -> 14400 | O37: =SUM(B37:M37) -> 172800 | P37: =IF(O26=0,0,O37/O26) -> 0.2
A38: Fixed Labor (Mgmt / Base Crew) | B38: =$B$8 -> 4200 | C38: =$B$8 -> 4200 | D38: =$B$8 -> 4200 | E38: =$B$8 -> 4200 | F38: =$B$8 -> 4200 | G38: =$B$8 -> 4200 | H38: =$B$8 -> 4200 | I38: =$B$8 -> 4200 | ... M38: =$B$8 -> 4200 | O38: =SUM(B38:M38) -> 50400 | P38: =IF(O26=0,0,O38/O26) -> 0.058333333
A39: Rent | B39: =$B$9 -> 7500 | C39: =$B$9 -> 7500 | D39: =$B$9 -> 7500 | E39: =$B$9 -> 7500 | F39: =$B$9 -> 7500 | G39: =$B$9 -> 7500 | H39: =$B$9 -> 7500 | I39: =$B$9 -> 7500 | ... M39: =$B$9 -> 7500 | O39: =SUM(B39:M39) -> 90000 | P39: =IF(O26=0,0,O39/O26) -> 0.10416667
A40: Utilities | B40: =$B$10*B$18 -> 1610 | C40: =$B$10*C$18 -> 1610 | D40: =$B$10*D$18 -> 1400 | E40: =$B$10*E$18 -> 1260 | F40: =$B$10*F$18 -> 1330 | G40: =$B$10*G$18 -> 1470 | H40: =$B$10*H$18 -> 1652 | I40: =$B$10*I$18 -> 1652 | ... M40: =$B$10*M$18 -> 1540 | O40: =SUM(B40:M40) -> 17514 | P40: =IF(O26=0,0,O40/O26) -> 0.020270833
A41: Marketing | B41: =B26*$B$11 -> 2116.8 | C41: =C26*$B$11 -> 2203.2 | D41: =D26*$B$11 -> 2203.2 | E41: =E26*$B$11 -> 2160 | F41: =F26*$B$11 -> 2203.2 | G41: =G26*$B$11 -> 2160 | H41: =H26*$B$11 -> 2095.2 | I41: =I26*$B$11 -> 2116.8 | ... M41: =M26*$B$11 -> 2160 | O41: =SUM(B41:M41) -> 25920 | P41: =IF(O26=0,0,O41/O26) -> 0.03
A42: Misc / Other | B42: =$B$12 -> 550 | C42: =$B$12 -> 550 | D42: =$B$12 -> 550 | E42: =$B$12 -> 550 | F42: =$B$12 -> 550 | G42: =$B$12 -> 550 | H42: =$B$12 -> 550 | I42: =$B$12 -> 550 | ... M42: =$B$12 -> 550 | O42: =SUM(B42:M42) -> 6600 | P42: =IF(O26=0,0,O42/O26) -> 0.0076388889
A43: Total OpEx | B43: =B37+B38+B39+B40+B41+B42 -> 30088.8 | C43: =C37+C38+C39+C40+C41+C42 -> 30751.2 | D43: =D37+D38+D39+D40+D41+D42 -> 30541.2 | E43: =E37+E38+E39+E40+E41+E42 -> 30070 | F43: =F37+F38+F39+F40+F41+F42 -> 30471.2 | G43: =G37+G38+G39+G40+G41+G42 -> 30280 | H43: =H37+H38+H39+H40+H41+H42 -> 29965.2 | I43: =I37+I38+I39+I40+I41+I42 -> 30130.8 | ... M43: =M37+M38+M39+M40+M41+M42 -> 30350 | O43: =SUM(B43:M43) -> 363234 | P43: =IF(O26=0,0,O43/O26) -> 0.42040972
A45: NET OPERATING INCOME (EBITDA) | B45: =B33-B43 -> 17892 | C45: =C33-C43 -> 19188 | D45: =D33-D43 -> 19398 | E45: =E33-E43 -> 18890 | F45: =F33-F43 -> 19468 | G45: =G33-G43 -> 18320 | H45: =H33-H43 -> 16967.28 | I45: =I33-I43 -> 17497.2 | ... M45: =M33-M43 -> 18610 | O45: =SUM(B45:M45) -> 223014.48 | P45: =IF(O26=0,0,O45/O26) -> 0.25811861
A46: NOI Margin % | B46: =IF(B26=0,0,B45/B26) -> 0.25357143 | C46: =IF(C26=0,0,C45/C26) -> 0.26127451 | D46: =IF(D26=0,0,D45/D26) -> 0.26413399 | E46: =IF(E26=0,0,E45/E26) -> 0.26236111 | F46: =IF(F26=0,0,F45/F26) -> 0.26508715 | G46: =IF(G26=0,0,G45/G26) -> 0.25444444 | H46: =IF(H26=0,0,H45/H26) -> 0.24294502 | I46: =IF(I26=0,0,I45/I26) -> 0.24797619 | ... M46: =IF(M26=0,0,M45/M26) -> 0.25847222 | O46: =IF(O26=0,0,O45/O26) -> 0.25811861 | P46: =IF(O26=0,0,O45/O26) -> 0.25811861

Sheet Arbys Location 3
A1: Arby's — Location 3 | Monthly P&L
A2: Blue = Editable Input | Black = Formula | Green = Linked | Yellow = Assumption cell | Amber = Seasonal index
A3: ASSUMPTIONS
A4: Monthly Base Revenue ($) | B4: 74000
A5: Food & Beverage Cost — Base (%) | B5: 0.3
A6: Paper & Supplies (%) | B6: 0.02
A7: Variable Labor (% of Revenue) | B7: 0.2
A8: Fixed Labor — Mgmt / Base Crew ($) | B8: 4200
A9: Monthly Rent ($) | B9: 8000
A10: Utilities — Base ($/mo) | B10: 1400
